# 오류처리

#### 오류처리란

* 프로그램이 오류를 일으켰을때 이것을 감지하고 회복시키는 일련의 과정
* 오류처리기능을 통하여 상황들을 구별하여 프로그램 자체적드로 오류를 해결, 사용자와 상호 작용을 통해 오류를 해결할 방향성을 제어 가능

#### 오류의 표현

* 오류는 Error라는 프로토콜을 준수하는 타입의 값을 통해 표현
* 프로토콜 Error는 사실상 요구사항이 없는 빈 프로토콜이지만, 오류를 표현하기 위한 타입은 Error프로토콜을 채택
* 오류종류를 나타내기 가장 좋은 기능은 열거형 연관 값을 통하여 오류에 관한 부가정보를 제공 가능

```swift
enum VendingMachineError: Error {
    case incalidSelection	// 유효하지않은 선택
    case insufficientFunds(coinsNeeded: Int) // 자금부족
    case outOfStock	// 재고부족
}
```

* 위와 같이 오류를 미리 예상한 다음, 오류로인한 동작이 진행시 오류를 던져 줌 (Throw Error)
* 오류를 던져 줄 때는 throw 구문을 사용

#### 오류 포착 및 처리

* 오류를 던질때 던져진 오류를 처리하기 위한 코드 작성이 필요

**스위프트에서 오류를 처리하기위한 방법**

* 함수에서 발생한 오류를 해당 함수를 호출한 코드에 알리는 방법
* do-chtch 구문을 이용하여 오류를 처리하는 방법
* 옵셔널값으로 오류를 처리하는 방법
* 오류가 발생하지 않을 것이라고 확신하는 방법 

#### 함수에서 발생한 오류 알리기

* try 키워드를 이용하여 던져진 오류 받기 가능, try, try?, try! 등으로 표현
* 함수, 메서드, 이니셜라이저의 매개변수 뒤에 throws 키워드를 사용하면 해당 함수, 메서드 이니셜라이저는 오류를 던지기 가능
* 일반적으로 func canotThrowErrors() ->String 기존 함수 혹은 메서드
* func canThrowErrors() throw -> String 와 같이 throw를 명시하면 오류 던지기 가능
* throws를 명시한 함수나 메서드 이니셜라이저는 명시하지 않은 함수 메서드 이니셜라이저와 구분

```swift
struct Item {
    var price: Int
    var count: Int
}
class VendingMachine {
    var inventory = [
        "Candy Bar": Item(price: 12, count: 7),
        "Chips": Item(price: 10, count: 4),
        "Biscuit": Item(price: 7, count: 11)
    ]
    var coinsDeposited = 0
    func dispense(sneck: String) {
        print("\(sneck) 제공")
    }
    func vend(itemnamed name: String) throws {
        guard let item = self.inventory[name] else {
            throw VendingMachineError.incalidSelection
        }
        guard item.count > 0 else {
            throw VendingMachineError.outOfStock
        }
        guard item.price <= self.coinsDeposited else {
            throw VendingMachineError.insufficientFunds(coinsNeeded: item.price - self.coinsDeposited)
        }
        self.coinsDeposited -= item.price
        var newItem = item
        newItem.count -= 1
        self.inventory[name] = newItem
        self.dispense(sneck: name)
    }
}
let favoriteSnacks = [
    "yagom": "Chips",
    "jinsung": "Biscuit",
    "heejin": "Chocolate"
]
func buyFavoriteSnack(person: String, vendingMachine: VendingMachine) throws {
    let snackName = favoriteSnacks[person] ?? "Candy Bar"
    try vendingMachine.vend(itemnamed: snackName)
}

struct PurchasedSnack {
    let name: String
    init(name: String, vendingMachine: VendingMachine) throws {
        try vendingMachine.vend(itemnamed: name)
        self.name = name
    }
}
let machine: VendingMachine = VendingMachine()
machine.coinsDeposited = 30

var purchase: PurchasedSnack = try PurchasedSnack(name: "Biscuit", vendingMachine: machine) // Biscuit 제공
print(purchase.name) // Biscuit
for (person, favoriteSnack) in favoriteSnacks {
    print(person, favoriteSnack)
    try buyFavoriteSnack(person: person, vendingMachine: machine)
}
// Biscuit
// yagom Chips
// Chips 제공
// jinsung Biscuit
// heejin Chocolate
// 오류 발생 (VendingMachineError.incalidSelection)
```

* 오류가 발생했을 때 흐름을 제어하기위한 guard를 통한 빠른종료 구문을 사용
* 특정 조건이 충족되지 않는다면 throws 키워드를 통해 오류를 던저서 오류가 발생했다는 것을 자신을 호출한 코드에 알림
* buyFavoriteSnack(person: vendingMachine:) 함수 호출 중 오류가 발생한 후 적절한 처리를 해주지 않으면 다음 코드가 정상적인 동작을 하지 않음

#### do-catch 구문을 이용하여 오류처리

* 함수, 메서드, 이니셜라이저등에서 오류를 던저주면 오류를 전달 받은 코드블록은 do-catch 구문을 사용하여 오류를 처리
* do 절 내부의 코드에서 오류를 던지면 catch 절에서 오류를 전달 받아 처리\

```swift
do {
    try 오류발생 가능 코드
    오류 발생이 없을시 실행코드
 } catch 오류 패턴 1 {
    처리 코드
 } catch 오류 패턴 2 where 추가조건 {
    처리 코드
 }
```

* catch절에서 처리할 오류의 종류를 기입, 기입하지 않을 경우 암시적 error라는 이름의 지역 상수가 오류의 내용

```swift
func buyFavoriteSnack(person: String, vendingMachine: VendingMachine) throws {
    let snackName = favoriteSnacks[person] ?? "Candy Bar"
    tryingVend(itemNamed: snackName, vendingMachine: vendingMachine)
}

struct PurchasedSnack {
    let name: String
    init(name: String, vendingMachine: VendingMachine) throws {
        tryingVend(itemNamed: name, vendingMachine: vendingMachine)
        self.name = name
    }
}

func tryingVend(itemNamed: String, vendingMachine: VendingMachine) {
    do {
        try vendingMachine.vend(itemnamed: itemNamed)
    } catch VendingMachineError.incalidSelection {
        print("유효하지 않은 선택")
    } catch VendingMachineError.outOfStock {
        print("품절")
    } catch VendingMachineError.insufficientFunds(let coinsNeeded) {
        print("자금 부족 - 동전 \(coinsNeeded)개를 추가로 지급해 주세요.")
    } catch {
        print("그외 오류 발생 : ", error)
    }
}
let machine: VendingMachine = VendingMachine()
machine.coinsDeposited = 20

var purchase: PurchasedSnack = try PurchasedSnack(name: "Biscuit", vendingMachine: machine) // Biscuit 제공
print(purchase.name) // Biscuit
purchase = try PurchasedSnack(name: "Ice Crem", vendingMachine: machine) // 유효하지 않은 선택
print(purchase.name) // Ice Crem

for (person, favoriteSnack) in favoriteSnacks {
    print(person, favoriteSnack)
    try buyFavoriteSnack(person: person, vendingMachine: machine)
} // yagom Chips // Chips 제공 // jinsung Biscuit // heejin Chocolate
// 오류발생 자금 부족 - 동전 4개를 추가로 지급해 주세요.
```

#### 옵셔널 값으로 오류처리

* try? 를 사용하여 옵셔널 값으로 변환하여 오류를 처리 가능
* try? 표현을 통해 동작하던 코드가 오류를 던지면 반환값은 nil

```swift
func someThrowingFunction(shouldThrowError: Bool) throws -> Int {
    if shouldThrowError {
        enum SomeError: Error {
            case justSomeError
        }
        throw SomeError.justSomeError
    }
    return 100
}
let x: Optional = try? someThrowingFunction(shouldThrowError: true)
print(x) // nil
let y: Optional = try? someThrowingFunction(shouldThrowError: false)
print(y) // Optional(100)
```

* try? 표현을 사용하여 호출한 함수가 오류를 던지면 반환값이 nil로 반환, 오류가 아니면 옵셔널 값으로 반환
* do-catch를 사용하지 않더라도 옵셔널을 사용하여 오류 처리 가능
* someThrowingFunction의 반환 값이 Int 라도 try?를 사용하면 옵셔널을 반환 

#### 오류가 발생하지 않을 것이라고 확신하는 방법

* 프로그래머가 오류를 던질 수 있는 함수 등을호출할 때 오류가 절대로 발생하지 않을 것이라고 확신하는 경우 try! 표현을 사용
* try! 표현 사용시 다른 !(느낌표)와 마찬가지로 오류가 발생시 런타임 오류를 발생

```swift
func someThrowingFunction(shouldThrowError: Bool) throws -> Int {
    if shouldThrowError {
        enum SomeError: Error {
            case justSomeError
        }
        throw SomeError.justSomeError
    }
    return 100
}
let y: Optional = try! someThrowingFunction(shouldThrowError: false)
print(y) // Optional (100)
let x: Optional = try! someThrowingFunction(shouldThrowError: true) // 런타임 오류!
```

#### 다시던지기

* 함수나 메서드는 rethrows 키워드를 사용하여 자신의 매개변수로 전달받은 함수가 오류를 던진다는 것을 나타낼 수 있음
* rethrow 키워드를 사용하여 다시던지기가 가능하기 위해서는 최소 하나이상의  오류 발생 가능한 함수를 매개 변수로 전달

```swift
func someThrowingFunction() throws {
    enum SomeError: Error {
        case justSomeError
    }
    throw SomeError.justSomeError
}
func someFunction(callback: () throws -> Void) rethrows {
    try callback() // 다시던지기 함수는 오류를 다시 던질 뿐 따로 처리하지 않음
}
do {
    try someFunction(callback: someThrowingFunction)
} catch {
    print(error)
} // justSomeError
```

* 다시던지기 함수 또는 메서드는 기본적으로 스스로 오류를 던지지 못함, 자신내부에 직접적으로 throw 구분을 사용할 수 없음
* 다시던지기 함수나 메서드 가오류를 던지는 함수를 do-catch 구문 내부에서 호출하고 catch 절 내부에서 다른 오류를 던짐으로써 오류를 던지는 함수에서 발생한 오류를 제어 가능
* 다시 던지기 내부의 catch 절에는 다시던지기 함수의 매개변수로 전달받은 오류던지기 함수만 호출하고 결과호 던저진 오류만 제어

```swift
func someThrowingFunction() throws {
    enum SomeError: Error {
        case justSomeError
    }
    throw SomeError.justSomeError
}
//다시 던지기 함수
func someFunction(callback: () throws -> Void) rethrows {
    enum AnotherError: Error {
        case justAnotherError
    }
    do {// 매개변수로 전달한 오류 던지기 함수이므로 catch 절에서 제어할 수 있음
        try callback()
    } catch {
        throw AnotherError.justAnotherError
    }
    do {// 매개변수로 전달한 오류 던지기 함수가 아니므로 catch 절에서 제어 불가
        try someThrowingFunction()
    } catch {
        throw AnotherError.justAnotherError // 오류발생
    }
    // catch 절 외부에서 단독으로 오류를 던질 수 없음, 오류 발생
    throw AnotherError.justAnotherError
}
```

* 부모클래스의 다시던지기 메서드는 자식클래스에서 던지기 메서드로 재정의 불가
* 부모클래스의 던지기 매서드는 자식클래스에서 다시던지기 재정의 가능
* 프로토콜의 다시던지기 메서드 요구사항은, 던지기 메서드 구현으로 충족 불가
* 프로토콜의 던지기 메서드는 다시던지기 메서드 작성으로 충족가능

```swift
protocol SomeProtocol {
    func someThrowingFunctionProtocol(callback: () throws -> Void) throws
    func someRethrowingFunctionProtocol(callback: () throws -> Void) rethrows
}
class someClass: SomeProtocol {
    func someThrowingFunction(callback: () throws -> Void) throws {}
    func someFunction(callback: () throws -> Void) rethrows {}
    //던지기 메서드는 다시던지기 메서드를 요구하는 프로토콜을 충족 불가 오류발생
     someRethrowingFunctionProtocol(callback: () throws -> Void) throws {
    }
    // 던지기 메서드는 던지기 메서드를 요구하는 프로토콜의 요구사항에 충족
    func someThrowingFunctionProtocol(callback: () throws -> Void) throws {
    }
}
class SomeChildClass: SomeClass {
    // 부모클래스의 던지기 메서드는 자식클래스에서 다시던지기 메서드로 재정의 가능
    func someThrowingFunction(callback: () throws -> Void) rethrows {}
    // 부모클래스의 다시던지기 메서드는 자식클래스에서 던지기 메서드로 재정의 불가 오류 발생
    func someFunction(callback: () throws -> Void) throws {}
}
```

#### 후처리 defer

* defer 구문을 사용하여 현재 코드 블록을 나가기 전에 꼭 실행해야 하는 코드를 작성 가능, defer구문은 코드가 블록을 어떤식으로 빠져나가든지 꼭 실행해야 하는 마무리 작업 수행
* defer 구문은 오류발생이나 정상으로 코드블록을 빠져나가던 무조건 실행
* defer 구문은 오류처리, 함수, 메서드, 반복문, 조건문등 보통의 코드에서 사용가능

```swift
for i in 0...2 {
    defer {
        print("A", terminator: " ")
    }
    print(i, terminator: " ")
    if i % 2 == 0 {
        defer {
            print("", terminator: "\n")
        }
        print("It's even", terminator: " ")
    }
}// 0 It's even
// A 1 A 2 It's even
// A
```

* defer 구문은 현재 코드범위를 벗어나기 직전에 실행
* defer 구문 내부에 break, return, 오류던지기 등의 구문 불가
* defer 구문이 여러개로 작성 되어 있으면 맨 마지막구문 부터 역순으로 실행\

```swift
func someFunction() {
    print("1")
    defer {
        print("2")
    }
    do {
        defer {
            print("3")
        }
        print("4")
    }
    defer {
        print("5")
    }
    print("6")
}
someFunction()
// 1 // 4 // 3 // 6 // 5 // 2
```

